<?xml version="1.0"?>
<robot xmlns:xacro="http://www.ros.org/wiki/xacro">

    <xacro:macro name="zeno_torso" >

        <link name="chest_link"/>
        <link name="pelvis_link"/>
        <link name="base_link"/>

        <!-- Torso joints -->
        <joint name="base_joint" type="fixed">
            <parent link="base_link"/>
            <child link="pelvis_link"/>
            <origin xyz="0 0 0" rpy="0 0 0" />
        </joint>

        <joint name="torso_joint" type="revolute">
            <parent link="pelvis_link"/>
            <child link="chest_link"/>
            <origin xyz="0.0 0.0 0.04" rpy="0 0 0" />
            <axis xyz="0 0 1"/>
            <limit velocity="1.0" effort="10" lower="-3.1415" upper="3.1415" />
        </joint>

    </xacro:macro>

</robot>