<?xml version="1.0"?>
<robot xmlns:xacro="http://www.ros.org/wiki/xacro">

    <xacro:macro name="zeno_arm" params="prefix reflect">

        <link name="${prefix}_shoulder_pitch_link"/>
        <link name="${prefix}_shoulder_roll_link"/>
        <link name="${prefix}_elbow_roll_link"/>
        <link name="${prefix}_elbow_pitch_link"/>
        <link name="${prefix}_wrist_roll_link"/>

        <!-- Right arm joints -->
        <joint name="${prefix}_shoulder_pitch_joint" type="revolute">
            <parent link="chest_link"/>
            <child link="${prefix}_shoulder_pitch_link"/>
            <origin xyz="0.0 ${reflect * 0.66} 0.70" rpy="0 ${shoulder_pitch_angle} ${pi/2 * reflect}" />
            <axis xyz="1 0 0"/>
            <limit velocity="1.0" effort="10" lower="-3.1415" upper="3.1415" />
        </joint>

        <joint name="${prefix}_shoulder_roll_joint" type="revolute">
            <parent link="${prefix}_shoulder_pitch_link"/>
            <child link="${prefix}_shoulder_roll_link"/>
            <origin xyz="0.222 0.0 0.36" rpy="0 ${pi/2} 0" />
            <axis xyz="0 1 0"/>
            <limit velocity="1.0" effort="10" lower="-3.1415" upper="3.1415" />
        </joint>

        <joint name="${prefix}_elbow_roll_joint" type="revolute">
            <parent link="${prefix}_shoulder_roll_link"/>
            <child link="${prefix}_elbow_roll_link"/>
            <origin xyz="0.7 0.0 0.0" rpy="${reflect * pi/2} 0 0" />
            <axis xyz="1 0 0"/>
            <limit velocity="1.0" effort="10" lower="-3.1415" upper="3.1415" />
        </joint>

        <joint name="${prefix}_elbow_pitch_joint" type="revolute">
            <parent link="${prefix}_elbow_roll_link"/>
            <child link="${prefix}_elbow_pitch_link"/>
            <origin xyz="0.25 0.0 -0.1" rpy="0 0 0" />
            <axis xyz="0 1 0"/>
            <limit velocity="1.0" effort="10" lower="-3.1415" upper="3.1415" />
        </joint>

        <joint name="${prefix}_wrist_roll_joint" type="revolute">
            <parent link="${prefix}_elbow_pitch_link"/>
            <child link="${prefix}_wrist_roll_link"/>
            <origin xyz="0.292 0.0 0.1" rpy="0 0 0" />
            <axis xyz="1 0 0"/>
            <limit velocity="1.0" effort="10" lower="-3.1415" upper="3.1415" />
        </joint>

    </xacro:macro>

</robot>